Workbook

Sheet Cover
A1: ETERNAL LIMITED (formerly Zomato Ltd) | NSE: ETERNAL | BSE: 543320 | E1: =Data_Sources!$D$15&" | "&Data_Sources!$E$15&" | "&Data_Sources!$F$15 -> Eternal Q4FY26 shareholders' letter | Annexure A & B (reconciliation to reported P&L) | https://b.zmtcdn.com/investor-relations/Eternal_Shareholders_Letter_Q4FY26_Results.pdf
A3: MODEL SCOPE
A4: ="Historicals: FY2023A–FY2026A (audited consolidated results, Ind AS; FY23A–FY24A partly incomplete — see Checks). Forecast: FY2027E–FY2034E. Valuation date: FY2026A balance sheet; market price "&TEXT(Assumptions!B142,"0")&"." -> Historicals: FY2023A–FY2026A (audited consolidated results, Ind AS; FY23A–FY24A partly incomplete — see Checks). Forecast: FY2027E–FY2034E. Valuation date: FY2026A balance sheet; market price 281.
A5: All figures in INR crore unless stated. FY = year ending 31 March. Segment build uses company-disclosed NOV / Adjusted Revenue / Adjusted EBITDA.
A6: Adjusted EBITDA = EBITDA + share-based payment expense − rent paid on Ind AS 116 leases (company definition, Q4FY26 letter).
A7: Every input is tagged with its source in column P of Assumptions and logged on the Data_Sources tab. Items without a locatable source are marked MANUAL – OPEN (yellow) and counted on Checks!B5.
A9: KEY OUTPUTS | B9: Unit | C9: FY2026A | D9: FY2034E
A10: B2C Net Order Value (NOV) | B10: INR Cr | C10: ='Revenue Schedule'!F16 -> 95960 | D10: ='Revenue Schedule'!N16 -> 880924.33
A11: Adjusted Revenue | B11: INR Cr | C11: ='Revenue Schedule'!F27 -> 55903 | D11: ='Revenue Schedule'!N27 -> 722008.39
A12: Adjusted EBITDA | B12: INR Cr | C12: =IS!G48 -> 1189 | D12: =IS!O48 -> 54902.172
A13: Adjusted EBITDA margin (% of adj. revenue) | B13: % | C13: =IS!G49 -> 0.021268984 | D13: =IS!O49 -> 0.076040905
A14: Profit after tax (PAT) | B14: INR Cr | C14: =IS!G29 -> 366 | D14: =IS!O29 -> 29682.14
A15: Blinkit dark stores (EOY) | B15: # | C15: =Assumptions!G16 -> 2243 | D15: =Assumptions!O16 -> 13343
A17: INVESTMENT CONCLUSION
A18: DCF intrinsic value / share | B18: INR | C18: =DCF!B32 -> 96.751813
A19: SOTP value / share (FY2030E order value × peer EV/NOV, discounted at WACC; independent of the DCF) | B19: INR | C19: =SOTP!D17 -> 238.90427
A20: ="Probability-weighted expected value / share ("&TEXT(Scenarios!B39,"0%")&" bear / "&TEXT(Scenarios!C39,"0%")&" base / "&TEXT(Scenarios!D39,"0%")&" bull)" -> Probability-weighted expected value / share (30% bear / 45% base / 25% bull) | B20: INR | C20: =Scenarios!B41 -> 206.12669
A21: Current market price (24-Jul-2026) | B21: INR | C21: =Assumptions!B142 -> 281
A22: Expected return vs market price | B22: % | C22: =C20/C21-1 -> -0.26645307
A23: ="Probability-weighted IRR to a FY2030 exit vs the "&TEXT(Assumptions!B160,"0%")&" hurdle" -> Probability-weighted IRR to a FY2030 exit vs the 18% hurdle | B23: % | C23: =Dashboard!B28 -> -0.073362586
A24: RECOMMENDATION | C24: =Dashboard!B9 -> AVOID / SELL — negative expected return
A25: Full decision page on the Dashboard tab; the written case, kill criteria and open items are on Memo.
A26: ="Balance check (BS row 33) FY26A gap "&TEXT(BS!G33,"#,##0")&" Cr carried flat; max change in forecast imbalance "&TEXT(MAX(INDEX(ABS(BS!H34:O34),0)),"#,##0")&" Cr. Full integrity status on the Checks tab (open items counted in Checks!B5)." -> Balance check (BS row 33) FY26A gap 15 Cr carried flat; max change in forecast imbalance 0 Cr. Full integrity status on the Checks tab (open items counted in Checks!B5).
A28: TAB GUIDE
A29: Index — navigation, key outputs and the model flow diagram; start here
A30: Assumptions — every input, with the filing / call reference in the source column
A31: Revenue Schedule — NOV, adjusted revenue and Adjusted EBITDA for all five reporting segments
A32: IS / BS / CFS — statements, the bridge from Adjusted EBITDA to reported PAT, and the company's own cash and treasury bridge
A33: FA_Schedule / Lease_Schedule / WC_Schedule / Cost Schedule / ESOP Schedule / Other Income Schedule — supporting builds
A34: OpMetrics — operating KPIs, plus store-level unit economics and cohort payback for Blinkit (section D)
A35: Ratios — growth, margins, unit economics, ROIC against WACC, and valuation at the market price
A36: DCF — 8-year FCFF on a cash-rent basis, WACC build-up, terminal value and a ROIC-consistent terminal cross-check
A37: SOTP — FY2030E segment order value × peer-anchored EV/NOV multiples (Comparable peer table), discounted at WACC; DCF–SOTP gap shown openly
A38: Sensitivity — five tables flexing WACC, terminal growth, exit multiple and the operating drivers
A39: Scenarios — bear / base / bull on the four operating businesses, probability-weighted to an expected value
... A45: Beta Calc / ERP & Rf / Comparable / Data_Sources — reference tabs behind the cost of capital, the peer set and every sourced figure

Sheet Index
A1: ETERNAL LIMITED — MASTER FINANCIAL MODEL | F1: =Data_Sources!$D$15&" | "&Data_Sources!$E$15&" | "&Data_Sources!$F$15 -> Eternal Q4FY26 shareholders' letter | Annexure A & B (reconciliation to reported P&L) | https://b.zmtcdn.com/investor-relations/Eternal_Shareholders_Letter_Q4FY26_Results.pdf
A2: Food delivery (Zomato) · Quick commerce (Blinkit) · Going-out (District) · B2B supplies (Hyperpure) | NSE: ETERNAL | FY2025A–FY2026A actuals, FY2027E–FY2034E forecast
A4: KEY MODEL OUTPUTS | B4: Unit | C4: FY2026A | D4: FY2030E | E4: FY2034E
A5: B2C Net Order Value | B5: INR Cr | C5: ='Revenue Schedule'!F16 -> 95960 | D5: ='Revenue Schedule'!J16 -> 415920.28 | E5: ='Revenue Schedule'!N16 -> 880924.33
A6: Adjusted revenue | B6: INR Cr | C6: ='Revenue Schedule'!F27 -> 55903 | D6: ='Revenue Schedule'!J27 -> 328544.99 | E6: ='Revenue Schedule'!N27 -> 722008.39
A7: Adjusted EBITDA | B7: INR Cr | C7: =IS!G48 -> 1189 | D7: =IS!K48 -> 17501.415 | E7: =IS!O48 -> 54902.172
A8: Adjusted EBITDA margin (% of adj. revenue) | B8: % | C8: =IS!G49 -> 0.021268984 | D8: =IS!K49 -> 0.053269462 | E8: =IS!O49 -> 0.076040905
A9: Profit after tax | B9: INR Cr | C9: =IS!G29 -> 366 | D9: =IS!K29 -> -3202.4177 | E9: =IS!O29 -> 29682.14
A10: Blinkit dark stores (EOY) | B10: # | C10: =OpMetrics!G5 -> 2243 | D10: =OpMetrics!K5 -> 7243 | E10: =OpMetrics!O5 -> 13343
A11: Closing cash & treasury investments | B11: INR Cr | C11: =CFS!G32 -> 17972 | D11: =CFS!K32 -> -20244.157 | E11: =CFS!O32 -> 31344.97
A13: DCF intrinsic value / share | B13: INR | C13: =DCF!B32 -> 96.751813
A14: SOTP value / share (discounted to today) | B14: =SOTP!D17 -> 238.90427 | C14: =SOTP!D19 -> -0.14980687
A15: Scenario range (bear / base / bull) | B15: INR | C15: =Scenarios!B35 -> 66.2238 | D15: =Scenarios!C35 -> 178.67861 | E15: =Scenarios!D35 -> 423.4167
A16: Current market price | B16: INR | C16: =Assumptions!B142 -> 281
A17: Upside / (downside) on DCF | B17: % | C17: =DCF!B34 -> -0.6556875
A18: Probability-weighted expected value / share | B18: INR | C18: =Scenarios!B41 -> 206.12669
A19: Probability-weighted IRR to a FY2030 exit (hurdle 18%) | B19: % | C19: =Dashboard!B28 -> -0.073362586
A20: RECOMMENDATION | C20: =Dashboard!B9 -> AVOID / SELL — negative expected return
A22: SHEET NAVIGATION | C22: What it does | D22: Key contents
A23: ── FRONT MATTER
A24: Cover | B24: → | C24: Scope, definitions and the investment conclusion | D24: Model period, Adjusted EBITDA definition, headline valuation and recommendation, full tab guide
A25: ── FOUNDATION
A26: Assumptions | B26: → | C26: Every input in one place | D26: Segment drivers, corporate P&L drivers, capex, WACC, schedule drivers; source for each in column M
A27: Revenue Schedule | B27: → | C27: Bottom-up build of all five segments | D27: NOV, adjusted revenue, Adjusted EBITDA; Blinkit built from stores x NOV per store per day
A28: ── STATEMENTS & SCHEDULES
A29: IS | B29: → | C29: P&L and the bridge to reported PAT | D29: Segment roll-up, share-based payment and lease-rent bridge; tax from Tax_Schedule (loss carry-forward)
A30: FA_Schedule | B30: → | C30: Fixed assets and D&A | D30: PPE, right-of-use and intangible roll-forwards; total D&A; capex; capital-intensity analysis
A31: Lease_Schedule | B31: → | C31: Debt and lease liabilities | D31: Nil bank debt, lease liability roll-forward, finance costs, leverage, interest cover, rent analysis
A32: WC_Schedule | B32: → | C32: Working capital | D32: Receivable / inventory / payable days, balances, net WC, cash conversion cycle
A33: Cost Schedule | B33: → | C33: Reported expense waterfall | D33: COGS, delivery, employee, marketing, other; gross margin, contribution, operating leverage
A34: Other Income Schedule | B34: → | C34: Treasury and other income | D34: Yield applied to the opening treasury balance, so no circular reference
A35: ESOP Schedule | B35: → | C35: Share-based payment charge only | D35: Feeds the Adjusted EBITDA add-back on the IS and the dilution build
A36: BS | B36: → | C36: Condensed balance sheet | D36: Schedule-driven assets and liabilities; no balancing line; genuine balance check in row 33
A37: CFS | B37: → | C37: Cash / treasury bridge | D37: The company's own bridge format: EBITDA, treasury income, capex, working capital, closing cash
A38: ── ANALYSIS
A39: OpMetrics | B39: → | C39: Operating KPIs and unit economics | D39: Stores, NOV per store per day, orders, NAOV, transacting customers, take rates
A40: Ratios | B40: → | C40: Ratio dashboard | D40: Growth, margins, returns, capital intensity, valuation at the current market price
A41: ── VALUATION
A42: DCF | B42: → | C42: 8-year FCFF valuation | D42: WACC build-up, FCFF on a cash-rent basis, terminal value, intrinsic value per share
A43: Share Count & Dilution | B43: → | C43: Share count roll-forward and ESOP dilution
...

Sheet Assumptions
A1: ASSUMPTIONS — all model inputs (blue = input, black = formula) | Q1: =Data_Sources!$D$26&" | "&Data_Sources!$E$26&" | "&Data_Sources!$F$26 -> Analyst estimate — not sourced from company disclosure | Judgement; sensitivity tested on the Sensitivity tab | n/a
A2: Item | B2: Unit | D2: FY2023A | E2: FY2024A | F2: FY2025A | G2: FY2026A | H2: FY2027E | I2: FY2028E | J2: FY2029E | K2: FY2030E | L2: FY2031E | M2: FY2032E | N2: FY2033E | O2: FY2034E | P2: Source / Rationale
D3: Actual | E3: Actual | F3: Actual | G3: Actual | H3: Forecast | I3: Forecast | J3: Forecast | K3: Forecast | L3: Forecast | M3: Forecast | N3: Forecast | O3: Forecast
A4: A. OPERATING ASSUMPTIONS — segment drivers, reported cost waterfall and corporate P&L
A6: FOOD DELIVERY (ZOMATO) | Q6: =Data_Sources!$D$20&" | "&Data_Sources!$E$20&" | "&Data_Sources!$F$20 -> Eternal Q4FY26 shareholders' letter | Q1 and Q7 of the Q&A | https://b.zmtcdn.com/investor-relations/Eternal_Shareholders_Letter_Q4FY26_Results.pdf
B7: % | P7: Mgmt: NOV growth to 18.8% YoY in Q4FY26, 'inching closer to our long-term expectation of 20%+' (Q4FY26 letter, Q1/Q7). Modelled at 20% in FY27& FY28 then fading to 13% as base because IBEF says CAGR till FY34 is 17-18% , and new players emerging in business like flipkart,ondc ,others.Mgt :margins have remained stable even as the order mix has shifted towards lower-value orders. Ultimately, we are optimizing for absolute Adjusted EBITDA (and not %), and the current tactics are working well to drive that ,future growth is the reduction of the minimum order value (MOV) for free delivery to INR 99 for Gold members(Q3,Q4FY25-26),still modelled at near inflation. | Q7: Mgmt: NOV growth to 18.8% YoY in Q4FY26, 'inching closer to our long-term expectation of 20%+' (Q4FY26 letter, Q1/Q7). Fading to 15% by FY34 because IBEF puts the industry CAGR to FY34 at 17-18% and new entrants (Flipkart, ONDC) are emerging. RETAINED AS A BENCHMARK ONLY: the build is driven by orders x NAOV, which implies c.18.4%. The gap between this row and row 7 is the gap between management's ambition and what the model actually assumes.
A8: Orders | B8: CR. | G8: ='Revenue Schedule'!F45 -> 97.93 | H8: =ROUND((G8*(1+H9)),1) -> 112.6 | I8: =ROUND((H8*(1+I9)),1) -> 129.5 | J8: =ROUND(I8*(1+J9),1) -> 148.9 | K8: =ROUND(J8*(1+K9),1) -> 171.2 | L8: =ROUND(K8*(1+L9),1) -> 195.2 | M8: =ROUND(L8*(1+M9),1) -> 222.5 | N8: =ROUND(M8*(1+N9),1) -> 253.7 | O8: =ROUND(N8*(1+O9),1) -> 289.2
A9: Orders growth | B9: % | G9: =IFERROR(G8/F8-1,"") | H9: 0.15 | I9: 0.15 | J9: 0.15 | K9: 0.15 | L9: 0.14 | M9: 0.14 | N9: 0.14 | O9: 0.14
A11: Net average order value (NAOV) | B11: INR | E11: ='Revenue Schedule'!D48 -> 364.81678 | F11: ='Revenue Schedule'!E48 -> 385.3424 | G11: ='Revenue Schedule'!F48 -> 387.96079 | H11: =ROUND((G11*(1+H12)),1) -> 399.6 | I11: =ROUND((H11*(1+I12)),1) -> 411.6 | J11: =ROUND((I11*(1+J12)),1) -> 423.9 | K11: =ROUND((J11*(1+K12)),1) -> 436.6 | L11: =ROUND((K11*(1+L12)),1) -> 449.7 | M11: =ROUND((L11*(1+M12)),1) -> 463.2 | N11: =ROUND((M11*(1+N12)),1) -> 477.1 | O11: =ROUND((N11*(1+O12)),1) -> 491.4
A12: Net AOV growth | B12: % | E12: =IFERROR(E11/D11-1,"") | F12: =IFERROR(F11/E11-1,"") -> 0.056262817 | G12: =IFERROR(G11/F11-1,"") -> 0.0067949616 | H12: 0.03 | I12: 0.03 | J12: 0.03 | K12: 0.03 | L12: 0.03 | M12: 0.03 | N12: 0.03 | O12: 0.03
A13: Adjusted revenue as % of NOV (take rate) | B13: % | G13: ='Revenue Schedule'!F52 -> 0.30789882 | H13: 0.315 | I13: 0.32 | J13: 0.325 | K13: 0.33 | L13: 0.33 | M13: 0.33 | N13: 0.33 | O13: 0.33 | P13: FY26A take rate 30.8% (adj. revenue 11,698 / NOV 37,993). Rising slowly on platform fee + ad monetisation, capped at 33% — mgmt says 'revenue per order and cost efficiencies have kept pace' (Q4FY26 letter, Q7).
A15: QUICK COMMERCE (BLINKIT) | Q15: =Data_Sources!$D$19&" | "&Data_Sources!$E$19&" | "&Data_Sources!$F$19 -> Eternal Q4FY26 shareholders' letter | Q2, Q3 and Q6 of the Q&A | https://b.zmtcdn.com/investor-relations/Eternal_Shareholders_Letter_Q4FY26_Results.pdf
A16: Dark stores (EOY) | B16: # | F16: ='Revenue Schedule'!E60 -> 1301 | G16: ='Revenue Schedule'!F60 -> 2243 | H16: =G16+H18 -> 3343 | I16: =H16+I18 -> 4543 | J16: =I16+J18 -> 5843 | K16: =J16+K18 -> 7243 | L16: =K16+L18 -> 8693 | M16: =L16+M18 -> 10193 | N16: =M16+N18 -> 11743 | O16: =N16+O18 -> 13343 | P16: Management is firmly on track to reach 3,000 stores by March 2027. they may aim for 3,500 to 4,000 stores by March 2027 to sustain Net Order Value (NOV) growth above 100% year-on-year.
A17: % growth | G17: =G16/F16-1 -> 0.72405842 | H17: =H16/G16-1 -> 0.49041462 | I17: =I16/H16-1 -> 0.35895902 | J17: =J16/I16-1 -> 0.28615452 | K17: =K16/J16-1 -> 0.23960294 | L17: =L16/K16-1 -> 0.20019329 | M17: =M16/L16-1 -> 0.17255263 | N17: =N16/M16-1 -> 0.15206514 | O17: =O16/N16-1 -> 0.13625138
A18: Net new dark stores added | B18: # | E18: =E16-D16 -> 0 | G18: =G16-F16 -> 942 | H18: 1100 | I18: 1200 | J18: 1300 | K18: 1400 | L18: 1450 | M18: 1500 | N18: 1550 | O18: 1600
A19: Blinkit throughput ladder selector (1 = Ladder A documented, 2 = Ladder B as-received) | B19: 1
A20: NOV per day, per store — OPERATIVE (selected ladder) | B20: INR '000 | E20: ='Revenue Schedule'!D66 -> 672 | F20: ='Revenue Schedule'!E66 -> 766 | G20: ='Revenue Schedule'!F66 -> 756 | H20: =CHOOSE($B$19,H22,H23) -> 1200 | I20: =CHOOSE($B$19,I22,I23) -> 1200 | J20: =CHOOSE($B$19,J22,J23) -> 1250 | K20: =CHOOSE($B$19,K22,K23) -> 1300 | L20: =CHOOSE($B$19,L22,L23) -> 1350 | M20: =CHOOSE($B$19,M22,M23) -> 1400 | N20: =CHOOSE($B$19,N22,N23) -> 1450 | O20: =CHOOSE($B$19,O22,O23) -> 1450 | P20: ="THROUGHPUT (price-setting). SOURCE: FY24A–FY26A NOV/store/day from the Eternal KPI databook (Data_Sources row 39): "&TEXT(E20,"#,##0")&" / "&TEXT(F20,"#,##0")&" / "&TEXT(G20,"#,##0")&" (INR '000). The 'INR 11 lakh' management figure had no document, date or page and is removed. FY26A START: "&TEXT(G20,"#,##0")&". BRIDGE: selector B19 = "&B19&"; FY27E "&TEXT(H20,"#,##0")&" is "&TEXT(H20/G20-1,"+0%")&" on FY26A while average stores grow "&TEXT('Revenue Schedule'!G64,"0%")&"; FY34E "&TEXT(O20,"#,##0")&". No disclosed bridge supports the FY27E step — MANUAL – OPEN. WRONG IF: new stores ramp slowly (OpMetrics maturity curve) or throughput falls as the network densifies, as it did in FY26A ("&TEXT(G21,"0.0%")&")." -> THROUGHPUT (price-setting). SOURCE: FY24A–FY26A NOV/store/day from the Eternal KPI databook (Data_Sources row 39): 672 / 766 / 756 (INR '000). The 'INR 11 lakh' management figure had no document, date or page and is removed. FY26A START: 756. BRIDGE: selector B19 = 1; FY27E 1,200 is +59% on FY26A while average stores grow 58%; FY34E 1,450. No disclosed bridge supports the FY27E step — MANUAL – OPEN. WRONG IF: new stores ramp slowly (OpMetrics maturity curve) or throughput falls as the network densifies, as it did in FY26A (-1.3%).
A21: % change | F21: =F20/E20-1 -> 0.13988095 | G21: =G20/F20-1 -> -0.01305483 | H21: =H20/G20-1 -> 0.58730159 | I21: =I20/H20-1 -> 0 | J21: =J20/I20-1 -> 0.041666667 | K21: =K20/J20-1 -> 0.04 | L21: =L20/K20-1 -> 0.038461538 | M21: =M20/L20-1 -> 0.037037037 | ... O21: =O20/N20-1 -> 0
A22: Ladder A — documented ladder (rationale in P20) | B22: INR '000 | H22: 1200 | I22: 1200 | J22: 1250 | K22: 1300 | L22: 1350 | M22: 1400 | N22: 1450 | O22: 1450
A23: Ladder B — ladder typed in Revenue Schedule H66:N66 as received | B23: INR '000 | H23: 1200 | I23: 1250 | J23: 1300 | K23: 1350 | L23: 1400 | M23: 1450 | N23: 1500 | O23: 1550
A24: Store ownership mix — COCO (company-operated) vs FOCO (local-partner operated; Eternal funds capex and holds the lease on both) | P24: Disclosure layer only. Eternal funds the capex (recognised as PPE), holds the Ind AS 116 right-of-use asset and lease liability, and pays the rent on BOTH formats; the local partner supplies day-to-day operations. Because no driver differs between the two, this block deliberately has no effect on revenue, EBITDA, capex, leases or valuation . it exists to show how much of the network is partner-run.
A25: FOCO share of the installed dark store base (FY2026A seed) | B25: % | G25: 0.5 | P25: Q2 FY23 shareholders' letter (10 Nov 2022) disclosed that almost half the dark store network was run by local partners, reiterated on later calls as roughly 50/50. Applied to the FY2026A closing base of 2,243 stores.
A26: FOCO share of net new dark stores | B26: % | D26: 0 | E26: 0 | F26: 0 | G26: 0 | H26: 0.5 | I26: 0.5 | J26: 0.5 | K26: 0.5 | L26: 0.5 | M26: 0.5 | N26: 0.5 | O26: 0.5 | P26: Management's stated long-term attempt and priority is that every new store is eventually run by a local partner, adding more trustworthy franchisees rather than expanding the company-run estate. Modelled as a ramp rather than a step: the 50% start is what the realised data implies, since partner share of the base held near half from FY23 to FY26 while the base grew several-fold, which is only possible if net new adds were already running near 50% partner-run.
A27: Net new FOCO stores added | B27: # | D27: =ROUND(D18*D26,0) -> 0 | E27: =ROUND(E18*E26,0) -> 0 | F27: =ROUND(F18*F26,0) -> 0 | G27: =ROUND(G18*G26,0) -> 0 | H27: =ROUND(H18*H26,0) -> 550 | I27: =ROUND(I18*I26,0) -> 600 | J27: =ROUND(J18*J26,0) -> 650 | K27: =ROUND(K18*K26,0) -> 700 | ... O27: =ROUND(O18*O26,0) -> 800 | P27: Net new stores x the partner share above. Rounded to whole stores.
A28: Net new COCO stores added | B28: # | D28: =D18-D27 -> 0 | E28: =E18-E27 -> 0 | F28: =F18-F27 -> 0 | G28: =G18-G27 -> 942 | H28: =H18-H27 -> 550 | I28: =I18-I27 -> 600 | J28: =J18-J27 -> 650 | K28: =K18-K27 -> 700 | ... O28: =O18-O27 -> 800 | P28: ="Residual of net new stores after partner adds: "&TEXT(H28,"#,##0")&" in FY2027E and "&TEXT(O28,"#,##0")&" in FY2034E at a "&TEXT(O26,"0%")&" FOCO share of adds (row 26)." -> Residual of net new stores after partner adds: 550 in FY2027E and 800 in FY2034E at a 50% FOCO share of adds (row 26).
A29: FOCO dark stores (EOY) | B29: # | D29: 0 | E29: =D29+E27 -> 0 | F29: =E29+F27 -> 0 | G29: =ROUND(G16*G25,0) -> 1122 | H29: =G29+H27 -> 1672 | I29: =H29+I27 -> 2272 | J29: =I29+J27 -> 2922 | K29: =J29+K27 -> 3622 | L29: =K29+L27 -> 4347 | M29: =L29+M27 -> 5097 | N29: =M29+N27 -> 5872 | O29: =N29+O27 -> 6672 | P29: ="Prior year closing plus net new partner stores. Reaches "&TEXT(O29,"#,##0")&" by FY2034E, or "&TEXT(O29/O16,"0%")&" of the network." -> Prior year closing plus net new partner stores. Reaches 6,672 by FY2034E, or 50% of the network.
A30: COCO dark stores (EOY) | B30: # | D30: =D16-D29 -> 0 | E30: =E16-E29 -> 0 | F30: =F16-F29 -> 1301 | G30: =G16-G29 -> 1121 | H30: =H16-H29 -> 1671 | I30: =I16-I29 -> 2271 | J30: =J16-J29 -> 2921 | K30: =K16-K29 -> 3621 | ... O30: =O16-O29 -> 6671 | P30: Taken as the residual against total dark stores on row 17 rather than accumulated independently, so the split can never drift away from the store count that actually drives revenue. Peaks near 2,966 and plateaus.
A31: Check: COCO + FOCO less total dark stores (must be nil) | H31: =H30-G30-H28 -> 0 | I31: =I30-H30-I28 -> 0 | J31: =J30-I30-J28 -> 0 | K31: =K30-J30-K28 -> 0 | L31: =L30-K30-L28 -> 0 | M31: =M30-L30-M28 -> 0 | N31: =N30-M30-N28 -> 0 | O31: =O30-N30-O28 -> 0 | P31: ="Integrity check: closing COCO must equal prior year plus net new COCO. Reported on the Checks tab (COCO + FOCO tie)." -> Integrity check: closing COCO must equal prior year plus net new COCO. Reported on the Checks tab (COCO + FOCO tie).
A33: Adjusted revenue as % of NOV (1P model) | B33: % | D33: ='Revenue Schedule'!C68/'Revenue Schedule'!C56 -> 0.14165202 | E33: ='Revenue Schedule'!D68/'Revenue Schedule'!D56 -> 0.21917547 | F33: ='Revenue Schedule'!E68/'Revenue Schedule'!E56 -> 0.23271199 | G33: ='Revenue Schedule'!F68/'Revenue Schedule'!F56 -> 0.77785785 | H33: 0.92 | I33: 0.92 | J33: 0.92 | K33: 0.92 | L33: 0.92 | M33: 0.92 | N33: 0.92 | O33: 0.92 | P33: Q4FY26 run-rate: revenue 13,232 / NOV 14,386 = 92% under the full inventory-led (1P) model adopted from Q1FY26. mgt expects no more increase in overall
Q34: =Data_Sources!$D$21&" | "&Data_Sources!$E$21&" | "&Data_Sources!$F$21 -> Eternal Q4FY26 shareholders' letter | Q9 of the Q&A | https://b.zmtcdn.com/investor-relations/Eternal_Shareholders_Letter_Q4FY26_Results.pdf
A35: GOING-OUT (DISTRICT)
A36: NOV growth | B36: % | D36: ='Revenue Schedule'!C73 -> 0 | E36: ='Revenue Schedule'!D73 -> 0 | F36: ='Revenue Schedule'!E73 -> 1.0524031 | G36: ='Revenue Schedule'!F73 -> 0.42000302 | H36: 0.4 | I36: 0.36 | J36: 0.32 | K36: 0.3 | L36: 0.25 | M36: 0.25 | N36: 0.25 | O36: 0.25 | P36: Going-out NOV grew 42% YoY in FY26 (mgmt asks investors to read the annual number, Q4FY26 letter Q9). Path sized to mgmt's $3bn NOV by FY30 guidance (Q9) and the analyst has taken flat 25% for beyond, as they will plan to go for international events too, if they are sizing up in the big and go through after bookmyshow as the competitor is that range.
A37: Revenue as % of NOV (take rate ) | B37: % | E37: ='Revenue Schedule'!D75/'Revenue Schedule'!D72 -> 0.079689922 | F37: ='Revenue Schedule'!E75/'Revenue Schedule'!E72 -> 0.11285693 | G37: ='Revenue Schedule'!F75/'Revenue Schedule'!F72 -> 0.10352165 | H37: 0.105 | I37: 0.11 | J37: 0.115 | K37: 0.12 | L37: 0.12 | M37: 0.12 | N37: 0.12 | O37: 0.12 | P37: FY26A: revenue 973 / NOV 9,399 = 10.4%. Mix shift toward higher-take live events and movies lifts it modestly.
Q38: =Data_Sources!$D$22&" | "&Data_Sources!$E$22&" | "&Data_Sources!$F$22 -> Eternal Q3FY26 shareholders' letter | Q&A on the Hyperpure business | https://b.zmtcdn.com/investor-relations/Eternal_Shareholders_Letter_Q3FY26_Results.pdf
A39: B2B SUPPLIES (HYPERPURE)
A40: Restaurant business revenue | B40: INR Cr | E40: 1970 | F40: 2699 | G40: 3722 | P40: Historical restaurant-business revenue (FY24A–FY26A) only. The duplicate forecast that sat in H40:O40 (ending ₹54,929 Cr) was deleted; the single operative Hyperpure forecast is Revenue Schedule row 83, driven by row 41 growth (each year reads its own column).
F41: =F40/E40-1 -> 0.37005076 | G41: =G40/F40-1 -> 0.37902927 | H41: 0.4 | I41: 0.4 | J41: 0.4 | K41: 0.4 | L41: 0.4 | M41: 0.4 | N41: 0.4 | O41: 0.4 | P41: ="Hyperpure restaurant revenue growth "&TEXT(H41,"0%")&" flat FY27E–FY34E. Guidance (Data_Sources row 22) covers ~3 years only; extending 40% for eight years has no basis — MANUAL – OPEN. FY26A actual "&TEXT(G41,"0.0%")&"." -> Hyperpure restaurant revenue growth 40% flat FY27E–FY34E. Guidance (Data_Sources row 22) covers ~3 years only; extending 40% for eight years has no basis — MANUAL – OPEN. FY26A actual 37.9%.
A42: Hyperpure non-restaurant revenue (B2B supplies to non-restaurant customers) | B42: INR Cr | H42: 0 | I42: 0 | J42: 0 | K42: 0 | L42: 0 | M42: 0 | N42: 0 | O42: 0 | P42: MANUAL – OPEN. Held at nil from FY27E on the stated rationale that non-restaurant B2B supply (largely to Blinkit) ends with the 1P transition. No locatable source in the workbook; FY26A was ₹1,644 Cr (Revenue Schedule!F84). Vipul to supply the disclosure.
A43: OTHERS (incl. Bistro)
A44: Revenue growth | B44: % | E44: ='Revenue Schedule'!D87/'Revenue Schedule'!C87-1 -> -0.90598291 | F44: ='Revenue Schedule'!E87/'Revenue Schedule'!D87-1 -> 0.36363636 | G44: ='Revenue Schedule'!F87/'Revenue Schedule'!E87-1 -> 1.9 | H44: 0.4 | I44: 0.35 | J44: 0.3 | K44: 0.25 | L44: 0.2 | M44: 0.15 | N44: 0.12 | O44: 0.1 | P44: Bistro and other early-stage bets small base (FY26A adj. revenue INR 87 Cr).
...

Sheet Revenue Schedule
A1: SEGMENT MODEL — NOV and Adjusted Revenue by business (INR Cr) | P1: Source (linked to Data_Sources)
A2: Line item | B2: Unit | C2: FY2023A | D2: FY2024A | E2: FY2025A | F2: FY2026A | G2: FY2027E | H2: FY2028E | I2: FY2029E | J2: FY2030E | K2: FY2031E | L2: FY2032E | M2: FY2033E | N2: FY2034E | O2: Source (historicals)
A3: NOV TO ADJUSTED REVENUE BRIDGE | P3: =Data_Sources!$D$15&" | "&Data_Sources!$E$15&" | "&Data_Sources!$F$15 -> Eternal Q4FY26 shareholders' letter | Annexure A & B (reconciliation to reported P&L) | https://b.zmtcdn.com/investor-relations/Eternal_Shareholders_Letter_Q4FY26_Results.pdf
A4: Food delivery NOV | B4: INR Cr | C4: =C42 -> 22501 | D4: =D42 -> 27478 | E4: =E42 -> 32862 | F4: =F42 -> 37993 | G4: =G42 -> 44994.96 | H4: =H42 -> 53302.2 | I4: =I42 -> 63118.71 | J4: =J42 -> 74745.92 | ... N4: =N42 -> 142112.88
A5: × Take rate (% of NOV) | B5: % | C5: =IFERROR(C51/C4,"n.a.") -> 0.27318786 | D5: =IFERROR(D51/D4,"n.a.") -> 0.28357231 | E5: =IFERROR(E51/E4,"n.a.") -> 0.28659242 | F5: =IFERROR(F51/F4,"n.a.") -> 0.30789882 | G5: =IFERROR(G51/G4,"n.a.") -> 0.315 | H5: =IFERROR(H51/H4,"n.a.") -> 0.32 | I5: =IFERROR(I51/I4,"n.a.") -> 0.325 | J5: =IFERROR(J51/J4,"n.a.") -> 0.33 | ... N5: =IFERROR(N51/N4,"n.a.") -> 0.33
A6: = Food delivery adjusted revenue | B6: INR Cr | C6: =IFERROR(C4*C5,"n.a.") -> 6147 | D6: =IFERROR(D4*D5,"n.a.") -> 7792 | E6: =IFERROR(E4*E5,"n.a.") -> 9418 | F6: =IFERROR(F4*F5,"n.a.") -> 11698 | G6: =IFERROR(G4*G5,"n.a.") -> 14173.412 | H6: =IFERROR(H4*H5,"n.a.") -> 17056.704 | I6: =IFERROR(I4*I5,"n.a.") -> 20513.581 | J6: =IFERROR(J4*J5,"n.a.") -> 24666.154 | ... N6: =IFERROR(N4*N5,"n.a.") -> 46897.25
A8: Quick commerce NOV | B8: INR Cr | C8: =C56 -> 5690 | D8: =D56 -> 10503 | E8: =E56 -> 22371 | F8: =F56 -> 48568 | G8: =G56 -> 122333.4 | H8: =H56 -> 172703.4 | I8: =I56 -> 236930.62 | J8: =J56 -> 310465.35 | ... N8: =N56 -> 663838.28
A9: × Take rate (% of NOV) | B9: % | C9: =IFERROR(C68/C8,"n.a.") -> 0.14165202 | D9: =IFERROR(D68/D8,"n.a.") -> 0.21917547 | E9: =IFERROR(E68/E8,"n.a.") -> 0.23271199 | F9: =IFERROR(F68/F8,"n.a.") -> 0.77785785 | G9: =IFERROR(G68/G8,"n.a.") -> 0.92 | H9: =IFERROR(H68/H8,"n.a.") -> 0.92 | I9: =IFERROR(I68/I8,"n.a.") -> 0.92 | J9: =IFERROR(J68/J8,"n.a.") -> 0.92 | ... N9: =IFERROR(N68/N8,"n.a.") -> 0.92 | O9: The step-change here is the whole story of FY26. Blinkit's take rate runs at 14-23% while it operates as a marketplace earning commission, then jumps to c.78% in FY26 when the inventory-led (1P) model means the full value of goods sold is recognised as revenue rather than just the commission. NOV grew 117% in FY26; adjusted revenue grew 626%. Almost all of that gap is accounting basis, not trading performance — read the two together, never revenue alone. FY23 and FY24 order value is on the NOV basis, so the denominator is consistent throughout.
A10: = Quick commerce adjusted revenue | B10: INR Cr | C10: =IFERROR(C8*C9,"n.a.") -> 806 | D10: =IFERROR(D8*D9,"n.a.") -> 2302 | E10: =IFERROR(E8*E9,"n.a.") -> 5206 | F10: =IFERROR(F8*F9,"n.a.") -> 37779 | G10: =IFERROR(G8*G9,"n.a.") -> 112546.73 | H10: =IFERROR(H8*H9,"n.a.") -> 158887.13 | I10: =IFERROR(I8*I9,"n.a.") -> 217976.18 | J10: =IFERROR(J8*J9,"n.a.") -> 285628.12 | ... N10: =IFERROR(N8*N9,"n.a.") -> 610731.21
A12: Going-out NOV | B12: INR Cr | C12: =IF(ISNUMBER(C72),C72,"n.a.") -> n.a. | D12: =IF(ISNUMBER(D72),D72,"n.a.") -> 3225 | E12: =IF(ISNUMBER(E72),E72,"n.a.") -> 6619 | F12: =IF(ISNUMBER(F72),F72,"n.a.") -> 9399 | G12: =IF(ISNUMBER(G72),G72,"n.a.") -> 13158.6 | H12: =IF(ISNUMBER(H72),H72,"n.a.") -> 17895.696 | I12: =IF(ISNUMBER(I72),I72,"n.a.") -> 23622.319 | J12: =IF(ISNUMBER(J72),J72,"n.a.") -> 30709.014 | ... N12: =IF(ISNUMBER(N72),N72,"n.a.") -> 74973.18 | O12: Going-out was not a separate reportable segment in FY23 — it sat inside 'Others' — so FY23 shows n.a. rather than nil. The B2C NOV line below uses SUM, which ignores text, so the FY23 B2C total correctly excludes going-out.
A13: × Take rate (% of NOV) | B13: % | C13: =IFERROR(C75/C12,"n.a.") -> n.a. | D13: =IFERROR(D75/D12,"n.a.") -> 0.079689922 | E13: =IFERROR(E75/E12,"n.a.") -> 0.11285693 | F13: =IFERROR(F75/F12,"n.a.") -> 0.10352165 | G13: =IFERROR(G75/G12,"n.a.") -> 0.105 | H13: =IFERROR(H75/H12,"n.a.") -> 0.11 | I13: =IFERROR(I75/I12,"n.a.") -> 0.115 | J13: =IFERROR(J75/J12,"n.a.") -> 0.12 | ... N13: =IFERROR(N75/N12,"n.a.") -> 0.12
A14: = Going-out adjusted revenue | B14: INR Cr | C14: =IFERROR(C12*C13,"n.a.") -> n.a. | D14: =IFERROR(D12*D13,"n.a.") -> 257 | E14: =IFERROR(E12*E13,"n.a.") -> 747 | F14: =IFERROR(F12*F13,"n.a.") -> 973 | G14: =IFERROR(G12*G13,"n.a.") -> 1381.653 | H14: =IFERROR(H12*H13,"n.a.") -> 1968.5266 | I14: =IFERROR(I12*I13,"n.a.") -> 2716.5667 | J14: =IFERROR(J12*J13,"n.a.") -> 3685.0817 | ... N14: =IFERROR(N12*N13,"n.a.") -> 8996.7815
A16: B2C NOV (food delivery + quick commerce + going-out) | B16: INR Cr | C16: =SUM(C4,C8,C12) -> 28191 | D16: =SUM(D4,D8,D12) -> 41206 | E16: =SUM(E4,E8,E12) -> 61852 | F16: =SUM(F4,F8,F12) -> 95960 | G16: =SUM(G4,G8,G12) -> 180486.96 | H16: =SUM(H4,H8,H12) -> 243901.3 | I16: =SUM(I4,I8,I12) -> 323671.65 | J16: =SUM(J4,J8,J12) -> 415920.28 | ... N16: =SUM(N4,N8,N12) -> 880924.33
A17: × Blended B2C take rate (% of NOV) | B17: % | C17: =IFERROR(SUM(C6,C10,C14)/C16,"n.a.") -> 0.246639 | D17: =IFERROR(SUM(D6,D10,D14)/D16,"n.a.") -> 0.25120128 | E17: =IFERROR(SUM(E6,E10,E14)/E16,"n.a.") -> 0.24851258 | F17: =IFERROR(SUM(F6,F10,F14)/F16,"n.a.") -> 0.52573989 | G17: =IFERROR(SUM(G6,G10,G14)/G16,"n.a.") -> 0.7097565 | H17: =IFERROR(SUM(H6,H10,H14)/H16,"n.a.") -> 0.72944409 | I17: =IFERROR(SUM(I6,I10,I14)/I16,"n.a.") -> 0.74521917 | J17: =IFERROR(SUM(J6,J10,J14)/J16,"n.a.") -> 0.75490273 | ... N17: =IFERROR(SUM(N6,N10,N14)/N16,"n.a.") -> 0.75673383
A18: = B2C adjusted revenue | B18: INR Cr | C18: =IFERROR(C16*C17,"n.a.") -> 6953 | D18: =IFERROR(D16*D17,"n.a.") -> 10351 | E18: =IFERROR(E16*E17,"n.a.") -> 15371 | F18: =IFERROR(F16*F17,"n.a.") -> 50450 | G18: =IFERROR(G16*G17,"n.a.") -> 128101.79 | H18: =IFERROR(H16*H17,"n.a.") -> 177912.36 | I18: =IFERROR(I16*I17,"n.a.") -> 241206.32 | J18: =IFERROR(J16*J17,"n.a.") -> 313979.36 | ... N18: =IFERROR(N16*N17,"n.a.") -> 666625.24
A20: Add: B2B supplies (Hyperpure) — no NOV, revenue recognised gross | B20: INR Cr | C20: =C80 -> 1506 | D20: =D80 -> 3172 | E20: =E80 -> 6196 | F20: =F80 -> 5366 | G20: =G80 -> 5210.8 | H20: =H80 -> 7295.12 | I20: =I80 -> 10213.168 | J20: =J80 -> 14298.435 | ... N20: =N80 -> 54928.869
A21: Add: Others (incl. Bistro) — no NOV | B21: INR Cr | C21: =C87 -> 234 | D21: =D87 -> 22 | E21: =E87 -> 30 | F21: =F87 -> 87 | G21: =G87 -> 121.8 | H21: =H87 -> 164.43 | I21: =I87 -> 213.759 | J21: =J87 -> 267.19875 | ... N21: =N87 -> 454.28063
A23: TOTAL ADJUSTED REVENUE | B23: INR Cr | C23: =SUM(C18,C20,C21) -> 8693 | D23: =SUM(D18,D20,D21) -> 13545 | E23: =SUM(E18,E20,E21) -> 21597 | F23: =SUM(F18,F20,F21) -> 55903 | G23: =SUM(G18,G20,G21) -> 133434.39 | H23: =SUM(H18,H20,H21) -> 185371.91 | I23: =SUM(I18,I20,I21) -> 251633.25 | J23: =SUM(J18,J20,J21) -> 328544.99 | ... N23: =SUM(N18,N20,N21) -> 722008.39
A24: Check vs consolidated total below (must be nil) | B24: INR Cr | C24: =C23-C27 -> 0 | D24: =D23-D27 -> 0 | E24: =E23-E27 -> 0 | F24: =F23-F27 -> 0 | G24: =G23-G27 -> 0 | H24: =H23-H27 -> 0 | I24: =I23-I27 -> 0 | J24: =J23-J27 -> 0 | ... N24: =N23-N27 -> 0
A26: CONSOLIDATED
A27: Total Adjusted Revenue | B27: INR Cr | C27: =SUM(C51,C68,C75,C80,C87) -> 8693 | D27: =SUM(D51,D68,D75,D80,D87) -> 13545 | E27: =E51+E68+E75+E80+E87 -> 21597 | F27: =F51+F68+F75+F80+F87 -> 55903 | G27: =G51+G68+G75+G80+G87 -> 133434.39 | H27: =H51+H68+H75+H80+H87 -> 185371.91 | I27: =I51+I68+I75+I80+I87 -> 251633.25 | J27: =J51+J68+J75+J80+J87 -> 328544.99 | K27: =K51+K68+K75+K80+K87 -> 415126.02 | L27: =L51+L68+L75+L80+L87 -> 512096.38 | ... N27: =N51+N68+N75+N80+N87 -> 722008.39 | O27: Cross-check against disclosure: FY23 8,693, FY24 13,545, FY25 21,597 and FY26 55,903 all tie to Eternal's disclosed consolidated adjusted revenue (sum of quarterly figures; FY25 reported as 21,581 in the AGM commentary, the difference being rounding of quarterly disclosures).
A28: % Growth | D28: =D27/C27-1 -> 0.55815024 | E28: =E27/D27-1 -> 0.5944629 | F28: =F27/E27-1 -> 1.5884614 | G28: =G27/F27-1 -> 1.3868915 | H28: =H27/G27-1 -> 0.38923634 | I28: =I27/H27-1 -> 0.35745082 | J28: =J27/I27-1 -> 0.30565016 | K28: =K27/J27-1 -> 0.26352868 | ... N28: =N27/M27-1 -> 0.16296999
A30: BRIDGE — REVENUE FROM OPERATIONS (IND AS) TO ADJUSTED REVENUE
A31: Revenue from operations (reported, Ind AS) | B31: INR Cr | C31: 7079 | D31: 12114 | E31: 20243 | F31: 54364 | G31: =G27-G33-G34 -> 130546.6 | H31: =H27-H33-H34 -> 181469.49 | I31: =I27-I33-I34 -> 246454.5 | J31: =J27-J33-J34 -> 321890.27 | K31: =K27-K33-K34 -> 406825.36 | L31: =L27-L33-L34 -> 501959.07 | M31: =M27-M33-M34 -> 608647.49 | N31: =N27-N33-N34 -> 707913.6
A32: Growth | B32: % | D32: =IFERROR(D31/C31-1,"") -> 0.71125865 | E32: =IFERROR(E31/D31-1,"") -> 0.67104177 | F32: =IFERROR(F31/E31-1,"") -> 1.6855703 | G32: =IFERROR(G31/F31-1,"") -> 1.4013428 | H32: =IFERROR(H31/G31-1,"") -> 0.39007439 | I32: =IFERROR(I31/H31-1,"") -> 0.35810436 | J32: =IFERROR(J31/I31-1,"") -> 0.30608393 | K32: =IFERROR(K31/J31-1,"") -> 0.26386352 | ... N32: =IFERROR(N31/M31-1,"") -> 0.16309296
A33: Add: Customer delivery charges (netted off in reported revenue) | B33: INR Cr | C33: =C27-C31-C34 -> 1614 | D33: =D27-D31-D34 -> 1431 | E33: =E27-E31-E34 -> 1354 | F33: =F27-F31-F34 -> 1539 | G33: =G16*G37 -> 2887.7914 | H33: =H16*H37 -> 3902.4207 | I33: =I16*I37 -> 5178.7465 | J33: =J16*J37 -> 6654.7245 | K33: =K16*K37 -> 8300.6545 | L33: =L16*L37 -> 10137.314 | M33: =M16*M37 -> 12184.003 | N33: =N16*N37 -> 14094.789
A34: Add: Customer platform fee & other adjustments | B34: INR Cr | C34: =Assumptions!D95 -> 0 | D34: =Assumptions!E95 -> 0 | E34: =Assumptions!F95 -> 0 | F34: =Assumptions!G95 -> 0 | G34: =Assumptions!H95 -> 0 | H34: =Assumptions!I95 -> 0 | I34: =Assumptions!J95 -> 0 | J34: =Assumptions!K95 -> 0 | ... N34: =Assumptions!O95 -> 0
A35: TOTAL ADJUSTED REVENUE | B35: INR Cr | C35: =C31+C33+C34 -> 8693 | D35: =D31+D33+D34 -> 13545 | E35: =E31+E33+E34 -> 21597 | F35: =F31+F33+F34 -> 55903 | G35: =G31+G33+G34 -> 133434.39 | H35: =H31+H33+H34 -> 185371.91 | I35: =I31+I33+I34 -> 251633.25 | J35: =J31+J33+J34 -> 328544.99 | ... N35: =N31+N33+N34 -> 722008.39
A36: Check vs consolidated total above (must be nil) | B36: INR Cr | C36: =IFERROR(ROUND(C35-C27,6),"n.a.") -> 0 | D36: =IFERROR(ROUND(D35-D27,6),"n.a.") -> 0 | E36: =IFERROR(ROUND(E35-E27,6),"n.a.") -> 0 | F36: =IFERROR(ROUND(F35-F27,6),"n.a.") -> 0 | G36: =IFERROR(ROUND(G35-G27,6),"n.a.") -> 0 | H36: =IFERROR(ROUND(H35-H27,6),"n.a.") -> 0 | I36: =IFERROR(ROUND(I35-I27,6),"n.a.") -> 0 | J36: =IFERROR(ROUND(J35-J27,6),"n.a.") -> 0 | ... N36: =IFERROR(ROUND(N35-N27,6),"n.a.") -> 0
A37: Memo: delivery charges as % of B2C NOV | B37: % | C37: =IFERROR(C33/C16,"") -> 0.057252315 | D37: =IFERROR(D33/D16,"") -> 0.034727952 | E37: =IFERROR(E33/E16,"") -> 0.021890966 | F37: =IFERROR(F33/F16,"") -> 0.016037932 | G37: =Assumptions!H76 -> 0.016 | H37: =Assumptions!I76 -> 0.016 | I37: =Assumptions!J76 -> 0.016 | J37: =Assumptions!K76 -> 0.016 | K37: =Assumptions!L76 -> 0.016 | L37: =Assumptions!M76 -> 0.016 | M37: =Assumptions!N76 -> 0.016 | N37: =Assumptions!O76 -> 0.016
A41: FOOD DELIVERY (ZOMATO) | P41: =Data_Sources!$D$11&" | "&Data_Sources!$E$11&" | "&Data_Sources!$F$11 -> Eternal Q4FY26 shareholders' letter | Annexure A — NOV (B2C business) | https://b.zmtcdn.com/investor-relations/Eternal_Shareholders_Letter_Q4FY26_Results.pdf
A42: Net Order Value (NOV) | B42: INR Cr | C42: 22501 | D42: 27478 | E42: 32862 | F42: 37993 | G42: =G45*G48 -> 44994.96 | H42: =H45*H48 -> 53302.2 | I42: =I45*I48 -> 63118.71 | J42: =J45*J48 -> 74745.92 | K42: =K45*K48 -> 87781.44 | L42: =L45*L48 -> 103062 | M42: =M45*M48 -> 121040.27 | N42: =N45*N48 -> 142112.88
A43: NOV growth | B43: % | D43: =D42/C42-1 -> 0.22119017 | E43: =E42/D42-1 -> 0.19593857 | F43: =F42/E42-1 -> 0.15613779 | G43: =G42/F42-1 -> 0.18429605 | H43: =H42/G42-1 -> 0.18462601 | I43: =I42/H42-1 -> 0.18416707 | J43: =J42/I42-1 -> 0.18421178 | K43: =K42/J42-1 -> 0.17439775 | ... N43: =N42/M42-1 -> 0.17409586
A45: Orders | B45: CR. | C45: =647/10 -> 64.7 | D45: =753.2/10 -> 75.32 | E45: =852.8/10 -> 85.28 | F45: =979.3/10 -> 97.93 | G45: =IFERROR(Assumptions!H8,"") -> 112.6 | H45: =IFERROR(Assumptions!I8,"") -> 129.5 | I45: =IFERROR(Assumptions!J8,"") -> 148.9 | J45: =IFERROR(Assumptions!K8,"") -> 171.2 | K45: =IFERROR(Assumptions!L8,"") -> 195.2 | L45: =IFERROR(Assumptions!M8,"") -> 222.5 | M45: =IFERROR(Assumptions!N8,"") -> 253.7 | N45: =IFERROR(Assumptions!O8,"") -> 289.2 | O45: Eternal quarterly KPI databook, sheet 'B. Annual data', section 2) Food delivery, row 'Orders (million)': FY23 647.0, FY24 753.2, FY25 852.8, FY26 979.3. Databook supplied by user upload (the IR site is JavaScript-rendered and its PDFs are image-only). Stated here in crore, so the formula divides the disclosed million figure by 10. Cross-check: the FY25 annual report also reports 853 mn orders against 753 mn in FY24. See Data_Sources row 38.
A46: % of Orders | B46: CR. | D46: =D45/C45-1 -> 0.16414219 | E46: =E45/D45-1 -> 0.13223579 | F46: =F45/E45-1 -> 0.1483349 | G46: =IFERROR(Assumptions!H9,"") -> 0.15 | H46: =IFERROR(Assumptions!I9,"") -> 0.15 | I46: =IFERROR(Assumptions!J9,"") -> 0.15 | J46: =IFERROR(Assumptions!K9,"") -> 0.15 | K46: =IFERROR(Assumptions!L9,"") -> 0.14 | L46: =IFERROR(Assumptions!M9,"") -> 0.14 | M46: =IFERROR(Assumptions!N9,"") -> 0.14 | N46: =IFERROR(Assumptions!O9,"") -> 0.14
A48: Net average order value (NAOV) | B48: INR | C48: =IFERROR(C42/C45,"") -> 347.77434 | D48: =IFERROR(D42/D45,"") -> 364.81678 | E48: =IFERROR(E42/E45,"") -> 385.3424 | F48: =IFERROR(F42/F45,"") -> 387.96079 | G48: =IFERROR(Assumptions!H11,"") -> 399.6 | H48: =IFERROR(Assumptions!I11,"") -> 411.6 | I48: =IFERROR(Assumptions!J11,"") -> 423.9 | J48: =IFERROR(Assumptions!K11,"") -> 436.6 | K48: =IFERROR(Assumptions!L11,"") -> 449.7 | L48: =IFERROR(Assumptions!M11,"") -> 463.2 | M48: =IFERROR(Assumptions!N11,"") -> 477.1 | N48: =IFERROR(Assumptions!O11,"") -> 491.4 | O48: This reproduces the databook's own disclosed net AOV of 365 / 385 / 388 for FY24-FY26 exactly, which validates the wiring. FY23 (348) has no disclosed counterpart , the databook publishes net AOV only from FY24, since NOV was first reported that year. See Data_Sources row 38.
A49: % change in orders | D49: =D48/C48-1 -> 0.049004301 | E49: =E48/D48-1 -> 0.056262817 | F49: =F48/E48-1 -> 0.0067949616 | G49: =G48/F48-1 -> 0.030001 | H49: =H48/G48-1 -> 0.03003003 | I49: =I48/H48-1 -> 0.029883382 | J49: =J48/I48-1 -> 0.029959896 | K49: =K48/J48-1 -> 0.030004581 | ... N49: =N48/M48-1 -> 0.029972752
A51: Adjusted revenue | B51: INR Cr | C51: 6147 | D51: 7792 | E51: 9418 | F51: 11698 | G51: =G42*Assumptions!H13 -> 14173.412 | H51: =H42*Assumptions!I13 -> 17056.704 | I51: =I42*Assumptions!J13 -> 20513.581 | J51: =J42*Assumptions!K13 -> 24666.154 | K51: =K42*Assumptions!L13 -> 28967.875 | L51: =L42*Assumptions!M13 -> 34010.46 | M51: =M42*Assumptions!N13 -> 39943.289 | N51: =N42*Assumptions!O13 -> 46897.25
A52: Take rate (% of NOV) | B52: % | C52: =C51/C42 -> 0.27318786 | D52: =D51/D42 -> 0.28357231 | E52: =E51/E42 -> 0.28659242 | F52: =F51/F42 -> 0.30789882 | G52: =G51/G42 -> 0.315 | H52: =H51/H42 -> 0.32 | I52: =I51/I42 -> 0.325 | J52: =J51/J42 -> 0.33 | ... N52: =N51/N42 -> 0.33
A55: QUICK COMMERCE (BLINKIT) | P55: =Data_Sources!$D$12&" | "&Data_Sources!$E$12&" | "&Data_Sources!$F$12 -> Eternal Q4FY26 shareholders' letter | Annexure A — quick commerce financial and operating metrics | https://b.zmtcdn.com/investor-relations/Eternal_Shareholders_Letter_Q4FY26_Results.pdf
...

Sheet Cost Schedule
A1: COST STRUCTURE — reported P&L expense waterfall and operating leverage (INR Cr) | Q1: =Data_Sources!$D$30&" | "&Data_Sources!$E$30&" | "&Data_Sources!$F$30 -> Eternal Q4FY26 audited consolidated P&L | Annexure D — expenses | https://b.zmtcdn.com/investor-relations/Eternal_Shareholders_Letter_Q4FY26_Results.pdf
A2: Line item | B2: Unit | D2: FY2023A | E2: FY2024A | F2: FY2025A | G2: FY2026A | H2: FY2027E | I2: FY2028E | J2: FY2029E | K2: FY2030E | L2: FY2031E | M2: FY2032E | N2: FY2033E | O2: FY2034E | P2: Source / Note
A4: A. EXPENSE BUILD (INR Cr)
A5: Revenue from operations (reported, Ind AS) | B5: INR Cr | D5: =IS!D6 -> 7079 | E5: =IS!E6 -> 12114 | F5: =IS!F6 -> 20243 | G5: =IS!G6 -> 54364 | H5: =IS!H6 -> 130546.6 | I5: =IS!I6 -> 181469.49 | J5: =IS!J6 -> 246454.5 | K5: =IS!K6 -> 321890.27 | ... O5: =IS!O6 -> 707913.6
A6: Cost of goods sold (purchases + materials + inventory change) | B6: INR Cr | D6: 1395 | E6: 2882 | F6: 5565 | G6: 30167 | H6: ='Revenue Schedule'!G68*(1-Assumptions!H71)+'Revenue Schedule'!G80*(1-Assumptions!H72) -> 83490.547 | I6: ='Revenue Schedule'!H68*(1-Assumptions!I71)+'Revenue Schedule'!H80*(1-Assumptions!I72) -> 116049.89 | J6: ='Revenue Schedule'!I68*(1-Assumptions!J71)+'Revenue Schedule'!I80*(1-Assumptions!J72) -> 158151.75 | K6: ='Revenue Schedule'!J68*(1-Assumptions!K71)+'Revenue Schedule'!J80*(1-Assumptions!K72) -> 206480.48 | L6: ='Revenue Schedule'!K68*(1-Assumptions!L71)+'Revenue Schedule'!K80*(1-Assumptions!L72) -> 260741.79 | M6: ='Revenue Schedule'!L68*(1-Assumptions!M71)+'Revenue Schedule'!L80*(1-Assumptions!M72) -> 323414.69 | N6: ='Revenue Schedule'!M68*(1-Assumptions!N71)+'Revenue Schedule'!M80*(1-Assumptions!N72) -> 390738.08 | O6: ='Revenue Schedule'!N68*(1-Assumptions!O71)+'Revenue Schedule'!N80*(1-Assumptions!O72) -> 455499.37 | P6: Forecast = quick commerce revenue x (1 − QC gross margin) + Hyperpure revenue x (1 − HP gross margin). Food delivery and going-out are commission businesses with no cost of goods.
A7: Delivery & related charges | B7: INR Cr | D7: 2537 | E7: 3915 | F7: 5728 | G7: 9065 | H7: =H5*Assumptions!H73 -> 21382.988 | I7: =I5*Assumptions!I73 -> 29149.417 | J7: =J5*Assumptions!J73 -> 38822.74 | K7: =K5*Assumptions!K73 -> 49716.125 | L7: =L5*Assumptions!L73 -> 61595.465 | M7: =M5*Assumptions!M73 -> 74474.999 | N7: =N5*Assumptions!N73 -> 89084.679 | O7: =O5*Assumptions!O73 -> 101472.75
A8: Employee benefits expense (incl. share-based payment) | B8: INR Cr | D8: 1465 | E8: 1659 | F8: 2558 | G8: 3536 | H8: =H5*Assumptions!H74 -> 7751.3333 | I8: =I5*Assumptions!I74 -> 10025.914 | J8: =J5*Assumptions!J74 -> 12604.786 | K8: =K5*Assumptions!K74 -> 15474.555 | L8: =L5*Assumptions!L74 -> 18728.351 | M8: =M5*Assumptions!M74 -> 22085.689 | N8: =N5*Assumptions!N74 -> 26164.731 | O8: =O5*Assumptions!O74 -> 29717.018
A9: of which: salaries, wages & bonus (excl. ESOP) | B9: INR Cr | D9: =IFERROR(D8-D10,"") -> 1465 | E9: =IFERROR(E8-E10,"") -> 1144 | F9: =IFERROR(F8-F10,"") -> 1760 | G9: =IFERROR(G8-G10,"") -> 2717 | H9: =IFERROR(H8-H10,"") -> 6901.3333 | I9: =IFERROR(I8-I10,"") -> 9145.914 | J9: =IFERROR(J8-J10,"") -> 11704.786 | K9: =IFERROR(K8-K10,"") -> 14554.555 | ... O9: =IFERROR(O8-O10,"") -> 28717.018
A10: of which: share-based payment (ESOP) | B10: INR Cr | D10: ='ESOP Schedule'!C5 -> 0 | E10: ='ESOP Schedule'!D5 -> 515 | F10: ='ESOP Schedule'!E5 -> 798 | G10: ='ESOP Schedule'!F5 -> 819 | H10: ='ESOP Schedule'!G5 -> 850 | I10: ='ESOP Schedule'!H5 -> 880 | J10: ='ESOP Schedule'!I5 -> 900 | K10: ='ESOP Schedule'!J5 -> 920 | ... O10: ='ESOP Schedule'!N5 -> 1000
A11: Advertisement & sales promotion | B11: INR Cr | D11: 1227 | E11: 1432 | F11: 1972 | G11: 3350 | H11: =H5*Assumptions!H75 -> 7617.6896 | I11: =I5*Assumptions!I75 -> 10025.914 | J11: =J5*Assumptions!J75 -> 12604.786 | K11: =K5*Assumptions!K75 -> 15803.801 | L11: =L5*Assumptions!L75 -> 19144.536 | M11: =M5*Assumptions!M75 -> 22599.31 | N11: =N5*Assumptions!N75 -> 26787.701 | O11: =O5*Assumptions!O75 -> 30441.824
A12: Other expenses (incl. cash lease rent, tech, G&A) — balancing | B12: INR Cr | D12: 1665 | E12: 2184 | F12: 3783 | G12: 7038 | H12: =H5*Assumptions!H77 -> 15595.185 | I12: =I5*Assumptions!I77 -> 19863.772 | J12: =J5*Assumptions!J77 -> 24512.531 | K12: =K5*Assumptions!K77 -> 28796.52 | L12: =L5*Assumptions!L77 -> 32326.617 | M12: =M5*Assumptions!M77 -> 34866.415 | N12: =N5*Assumptions!N77 -> 36190.589 | O12: =O5*Assumptions!O77 -> 38935.248 | P12: Forecast = revenue from operations × Assumptions row 77 (% of revenue driver). No longer a balancing line; EBITDA is now the output of this waterfall.
A13: of which: IT support, server & communication | B13: INR Cr | D13: =IFERROR(D12*Assumptions!D79,"") -> 283.05 | E13: =IFERROR(E12*Assumptions!E79,"") -> 371.28 | F13: =IFERROR(F12*Assumptions!F79,"") -> 643.11 | G13: =IFERROR(G12*Assumptions!G79,"") -> 1196.46 | H13: =IFERROR(H12*Assumptions!H79,"") -> 2651.1814 | I13: =IFERROR(I12*Assumptions!I79,"") -> 3376.8413 | J13: =IFERROR(J12*Assumptions!J79,"") -> 4167.1302 | K13: =IFERROR(K12*Assumptions!K79,"") -> 4895.4084 | ... O13: =IFERROR(O12*Assumptions!O79,"") -> 6618.9922
A14: of which: outsourced support costs | B14: INR Cr | D14: =IFERROR(D12*Assumptions!D80,"") -> 249.75 | E14: =IFERROR(E12*Assumptions!E80,"") -> 327.6 | F14: =IFERROR(F12*Assumptions!F80,"") -> 567.45 | G14: =IFERROR(G12*Assumptions!G80,"") -> 1055.7 | H14: =IFERROR(H12*Assumptions!H80,"") -> 2339.2777 | I14: =IFERROR(I12*Assumptions!I80,"") -> 2979.5658 | J14: =IFERROR(J12*Assumptions!J80,"") -> 3676.8796 | K14: =IFERROR(K12*Assumptions!K80,"") -> 4319.478 | ... O14: =IFERROR(O12*Assumptions!O80,"") -> 5840.2872
A15: of which: payment gateway & related charges | B15: INR Cr | D15: =IFERROR(D12*Assumptions!D81,"") -> 199.8 | E15: =IFERROR(E12*Assumptions!E81,"") -> 262.08 | F15: =IFERROR(F12*Assumptions!F81,"") -> 453.96 | G15: =IFERROR(G12*Assumptions!G81,"") -> 844.56 | H15: =IFERROR(H12*Assumptions!H81,"") -> 1871.4222 | I15: =IFERROR(I12*Assumptions!I81,"") -> 2383.6527 | J15: =IFERROR(J12*Assumptions!J81,"") -> 2941.5037 | K15: =IFERROR(K12*Assumptions!K81,"") -> 3455.5824 | ... O15: =IFERROR(O12*Assumptions!O81,"") -> 4672.2298
A16: of which: rent, rates & taxes | B16: INR Cr | D16: =IFERROR(D12*Assumptions!D82,"") -> 133.2 | E16: =IFERROR(E12*Assumptions!E82,"") -> 174.72 | F16: =IFERROR(F12*Assumptions!F82,"") -> 302.64 | G16: =IFERROR(G12*Assumptions!G82,"") -> 563.04 | H16: =IFERROR(H12*Assumptions!H82,"") -> 1247.6148 | I16: =IFERROR(I12*Assumptions!I82,"") -> 1589.1018 | J16: =IFERROR(J12*Assumptions!J82,"") -> 1961.0024 | K16: =IFERROR(K12*Assumptions!K82,"") -> 2303.7216 | ... O16: =IFERROR(O12*Assumptions!O82,"") -> 3114.8199
A17: of which: other (residual) | B17: INR Cr | D17: =IFERROR(D12-SUM(D13:D16),"") -> 799.2 | E17: =IFERROR(E12-SUM(E13:E16),"") -> 1048.32 | F17: =IFERROR(F12-SUM(F13:F16),"") -> 1815.84 | G17: =IFERROR(G12-SUM(G13:G16),"") -> 3378.24 | H17: =IFERROR(H12-SUM(H13:H16),"") -> 7485.6887 | I17: =IFERROR(I12-SUM(I13:I16),"") -> 9534.6106 | J17: =IFERROR(J12-SUM(J13:J16),"") -> 11766.015 | K17: =IFERROR(K12-SUM(K13:K16),"") -> 13822.329 | ... O17: =IFERROR(O12-SUM(O13:O16),"") -> 18688.919
A19: TOTAL OPERATING EXPENSES | B19: INR Cr | D19: =D6+D7+D8+D11+D12 -> 8289 | E19: =E6+E7+E8+E11+E12 -> 12072 | F19: =F6+F7+F8+F11+F12 -> 19606 | G19: =G6+G7+G8+G11+G12 -> 53156 | H19: =H6+H7+H8+H11+H12 -> 135837.74 | I19: =I6+I7+I8+I11+I12 -> 185114.91 | J19: =J6+J7+J8+J11+J12 -> 246696.59 | K19: =K6+K7+K8+K11+K12 -> 316271.48 | ... O19: =O6+O7+O8+O11+O12 -> 656066.2
A20: EBITDA (reported basis) — check vs IS row 35 | B20: INR Cr | D20: =D5-D19 -> -1210 | E20: =E5-E19 -> 42 | F20: =F5-F19 -> 637 | G20: =G5-G19 -> 1208 | H20: =H5-H19 -> -5291.141 | I20: =I5-I19 -> -3645.4179 | J20: =J5-J19 -> -242.08899 | K20: =K5-K19 -> 5618.783 | ... O20: =O5-O19 -> 51847.403
A21: Check: waterfall EBITDA vs IS EBITDA (must be nil; fails if any IS line link breaks) | B21: INR Cr | D21: =ROUND(D20-IS!D16,2) -> 0 | E21: =ROUND(E20-IS!E16,2) -> 0 | F21: =ROUND(F20-IS!F16,2) -> 0 | G21: =ROUND(G20-IS!G16,2) -> 0 | H21: =ROUND(H20-IS!H16,2) -> 0 | I21: =ROUND(I20-IS!I16,2) -> 0 | J21: =ROUND(J20-IS!J16,2) -> 0 | K21: =ROUND(K20-IS!K16,2) -> 0 | ... O21: =ROUND(O20-IS!O16,2) -> 0 | P21: Historical difference reflects reported revenue vs adjusted revenue (delivery charges and platform fees added back in the adjusted measure).
A23: B. COST WATERFALL AS % OF REVENUE FROM OPERATIONS
A24: Cost of goods sold | B24: % | D24: =D6/D5 -> 0.19706173 | E24: =E6/E5 -> 0.23790655 | F24: =F6/F5 -> 0.27490985 | G24: =G6/G5 -> 0.55490766 | H24: =H6/H5 -> 0.63954592 | I24: =I6/I5 -> 0.63950084 | J24: =J6/J5 -> 0.64170769 | K24: =K6/K5 -> 0.64146234 | ... O24: =O6/O5 -> 0.6434392
A25: Delivery & related charges | B25: % | D25: =D7/D5 -> 0.35838395 | E25: =E7/E5 -> 0.32317979 | F25: =F7/F5 -> 0.28296201 | G25: =G7/G5 -> 0.16674638 | H25: =H7/H5 -> 0.16379582 | I25: =I7/I5 -> 0.16062985 | J25: =J7/J5 -> 0.15752498 | K25: =K7/K5 -> 0.15445054 | ... O25: =O7/O5 -> 0.14334058
A26: Employee benefits | B26: % | D26: =D8/D5 -> 0.20695013 | E26: =E8/E5 -> 0.13694898 | F26: =F8/F5 -> 0.12636467 | G26: =G8/G5 -> 0.065043043 | H26: =H8/H5 -> 0.059375986 | I26: =I8/I5 -> 0.055248483 | J26: =J8/J5 -> 0.051144473 | K26: =K8/K5 -> 0.048074009 | ... O26: =O8/O5 -> 0.041978312
A27: Advertisement & sales promotion | B27: % | D27: =D11/D5 -> 0.17332957 | E27: =E11/E5 -> 0.11821034 | F27: =F11/F5 -> 0.097416391 | G27: =G11/G5 -> 0.061621661 | H27: =H11/H5 -> 0.058352262 | I27: =I11/I5 -> 0.055248483 | J27: =J11/J5 -> 0.051144473 | K27: =K11/K5 -> 0.04909686 | ... O27: =O11/O5 -> 0.043002173
A28: Other expenses | B28: % | D28: =D12/D5 -> 0.23520271 | E28: =E12/E5 -> 0.18028727 | F28: =F12/F5 -> 0.18687942 | G28: =G12/G5 -> 0.12946067 | H28: =H12/H5 -> 0.11946067 | I28: =I12/I5 -> 0.10946067 | J28: =J12/J5 -> 0.099460673 | K28: =K12/K5 -> 0.089460673 | ... O28: =O12/O5 -> 0.055
A30: TOTAL OPEX % of revenue from operations | B30: % | D30: =D19/D5 -> 1.1709281 | E30: =E19/E5 -> 0.99653294 | F30: =F19/F5 -> 0.96853233 | G30: =G19/G5 -> 0.97777941 | H30: =H19/H5 -> 1.0405307 | I30: =I19/I5 -> 1.0200883 | J30: =J19/J5 -> 1.0009823 | K30: =K19/K5 -> 0.98254441 | ... O30: =O19/O5 -> 0.92676027
A31: EBITDA margin (% of revenue from operations) | B31: % | D31: =D20/D5 -> -0.1709281 | E31: =E20/E5 -> 0.0034670629 | F31: =F20/F5 -> 0.031467668 | G31: =G20/G5 -> 0.022220587 | H31: =H20/H5 -> -0.040530668 | I31: =I20/I5 -> -0.020088324 | J31: =J20/J5 -> -0.00098228675 | K31: =K20/K5 -> 0.017455585 | ... O31: =O20/O5 -> 0.073239733
A34: C. DETAIL ANALYSIS — gross margin & operating leverage
A36: Gross profit ( Operational revenue − COGS) | B36: INR Cr | D36: =D5-D6 -> 5684 | E36: =E5-E6 -> 9232 | F36: =F5-F6 -> 14678 | G36: =G5-G6 -> 24197 | H36: =H5-H6 -> 47056.055 | I36: =I5-I6 -> 65419.599 | J36: =J5-J6 -> 88302.753 | K36: =K5-K6 -> 115409.78 | ... O36: =O5-O6 -> 252414.24
A37: Gross margin | B37: % | D37: =D36/D5 -> 0.80293827 | E37: =E36/E5 -> 0.76209345 | F37: =F36/F5 -> 0.72509015 | G37: =G36/G5 -> 0.44509234 | H37: =H36/H5 -> 0.36045408 | I37: =I36/I5 -> 0.36049916 | J37: =J36/J5 -> 0.35829231 | K37: =K36/K5 -> 0.35853766 | ... O37: =O36/O5 -> 0.3565608
A39: Contribution after delivery costs | B39: INR Cr | D39: =D36-D7 -> 3147 | E39: =E36-E7 -> 5317 | F39: =F36-F7 -> 8950 | G39: =G36-G7 -> 15132 | H39: =H36-H7 -> 25673.067 | I39: =I36-I7 -> 36270.182 | J39: =J36-J7 -> 49480.013 | K39: =K36-K7 -> 65693.659 | ... O39: =O36-O7 -> 150941.49
A40: as % of revenue from operations | B40: % | D40: =D39/D5 -> 0.44455432 | E40: =E39/E5 -> 0.43891365 | F40: =F39/F5 -> 0.44212814 | G40: =G39/G5 -> 0.27834596 | H40: =H39/H5 -> 0.19665825 | I40: =I39/I5 -> 0.19986932 | J40: =J39/J5 -> 0.20076733 | K40: =K39/K5 -> 0.20408713 | ... O40: =O39/O5 -> 0.21322022
A42: Fixed-cost base (employee + advertising + other) | B42: INR Cr | D42: =D8+D11+D12 -> 4357 | E42: =E8+E11+E12 -> 5275 | F42: =F8+F11+F12 -> 8313 | G42: =G8+G11+G12 -> 13924 | H42: =H8+H11+H12 -> 30964.208 | I42: =I8+I11+I12 -> 39915.6 | J42: =J8+J11+J12 -> 49722.102 | K42: =K8+K11+K12 -> 60074.876 | ... O42: =O8+O11+O12 -> 99094.09
A43: as % of revenue from operations | B43: % | D43: =D42/D5 -> 0.61548241 | E43: =E42/E5 -> 0.43544659 | F43: =F42/F5 -> 0.41066048 | G43: =G42/G5 -> 0.25612538 | H43: =H42/H5 -> 0.23718892 | I43: =I42/I5 -> 0.21995764 | J43: =J42/J5 -> 0.20174962 | K43: =K42/K5 -> 0.18663154 | ... O43: =O42/O5 -> 0.13998049
A45: Incremental EBITDA margin (ΔEBITDA / Δrevenue) | B45: % | E45: =(E20-D20)/(E5-D5) -> 0.24865938 | F45: =(F20-E20)/(F5-E5) -> 0.073194735 | G45: =(G20-F20)/(G5-F5) -> 0.016734562 | H45: =(H20-G20)/(H5-G5) -> -0.085310042 | I45: =(I20-H20)/(I5-H5) -> 0.032317946 | J45: =(J20-I20)/(J5-I5) -> 0.05237098 | K45: =(K20-J20)/(K5-J5) -> 0.077693546 | L45: =(L20-K20)/(L5-K5) -> 0.10207586 | ... O45: =(O20-N20)/(O5-N5) -> 0.12255637 | P45: The single most important operating-leverage statistic: how much of each incremental rupee of revenue drops to EBITDA.
A48: READ-THROUGH
A49: 1. The FY26 cost structure is not comparable to FY25. Moving Blinkit to an inventory-led (1P) model pulled the full value of goods sold into both revenue and cost — COGS jumped from 26% to 54% of adjusted revenue with no change in underlying economics.
A50: 2. Because of that, gross margin is now the number to watch, not EBITDA margin on revenue. Blinkit's gross profit ran at 26.9% of NOV in Q4FY26 (29% of segment revenue); private label, ad income and Hyperpure sourcing are the levers.
A51: 3. Delivery & related charges (16% of adjusted revenue) are the largest controllable cost. Batching, store density and shorter trip distances are what convert NOV growth into margin.
A52: 4. The fixed-cost base (people, marketing, G&A) is where operating leverage lives. Holding it roughly flat in rupee terms while NOV compounds 25-30% is the entire path to the $1bn Adjusted EBITDA ambition.
...

Sheet IS
A1: INCOME STATEMENT — Eternal Limited, consolidated (INR Cr) | Q1: Source (linked to Data_Sources)
A2: Line item | B2: Unit | D2: FY2023A | E2: FY2024A | F2: FY2025A | G2: FY2026A | H2: FY2027E | I2: FY2028E | J2: FY2029E | K2: FY2030E | L2: FY2031E | M2: FY2032E | N2: FY2033E | O2: FY2034E | P2: Source / Note
A5: A. REPORTED P&L (IND AS) | Q5: =Data_Sources!$D$30&" | "&Data_Sources!$E$30&" | "&Data_Sources!$F$30 -> Eternal Q4FY26 audited consolidated P&L | Annexure D — expenses | https://b.zmtcdn.com/investor-relations/Eternal_Shareholders_Letter_Q4FY26_Results.pdf
A6: Revenue from operations | B6: INR Cr | D6: ='Revenue Schedule'!C31 -> 7079 | E6: ='Revenue Schedule'!D31 -> 12114 | F6: ='Revenue Schedule'!E31 -> 20243 | G6: ='Revenue Schedule'!F31 -> 54364 | H6: ='Revenue Schedule'!G31 -> 130546.6 | I6: ='Revenue Schedule'!H31 -> 181469.49 | J6: ='Revenue Schedule'!I31 -> 246454.5 | K6: ='Revenue Schedule'!J31 -> 321890.27 | ... O6: ='Revenue Schedule'!N31 -> 707913.6
A7: Less: Cost of goods sold | B7: INR Cr | D7: =-'Cost Schedule'!D6 -> -1395 | E7: =-'Cost Schedule'!E6 -> -2882 | F7: =-'Cost Schedule'!F6 -> -5565 | G7: =-'Cost Schedule'!G6 -> -30167 | H7: =-'Cost Schedule'!H6 -> -83490.547 | I7: =-'Cost Schedule'!I6 -> -116049.89 | J7: =-'Cost Schedule'!J6 -> -158151.75 | K7: =-'Cost Schedule'!K6 -> -206480.48 | ... O7: =-'Cost Schedule'!O6 -> -455499.37
A9: GROSS PROFIT | B9: INR Cr | D9: =D6+D7 -> 5684 | E9: =E6+E7 -> 9232 | F9: =F6+F7 -> 14678 | G9: =G6+G7 -> 24197 | H9: =H6+H7 -> 47056.055 | I9: =I6+I7 -> 65419.599 | J9: =J6+J7 -> 88302.753 | K9: =K6+K7 -> 115409.78 | ... O9: =O6+O7 -> 252414.24
A10: Gross margin (% of revenue) | B10: % | D10: =IFERROR(D9/D6,"") -> 0.80293827 | E10: =IFERROR(E9/E6,"") -> 0.76209345 | F10: =IFERROR(F9/F6,"") -> 0.72509015 | G10: =IFERROR(G9/G6,"") -> 0.44509234 | H10: =IFERROR(H9/H6,"") -> 0.36045408 | I10: =IFERROR(I9/I6,"") -> 0.36049916 | J10: =IFERROR(J9/J6,"") -> 0.35829231 | K10: =IFERROR(K9/K6,"") -> 0.35853766 | ... O10: =IFERROR(O9/O6,"") -> 0.3565608
A11: Less: Employee benefits expense (incl. ESOP) | B11: INR Cr | D11: =-'Cost Schedule'!D8 -> -1465 | E11: =-'Cost Schedule'!E8 -> -1659 | F11: =-'Cost Schedule'!F8 -> -2558 | G11: =-'Cost Schedule'!G8 -> -3536 | H11: =-'Cost Schedule'!H8 -> -7751.3333 | I11: =-'Cost Schedule'!I8 -> -10025.914 | J11: =-'Cost Schedule'!J8 -> -12604.786 | K11: =-'Cost Schedule'!K8 -> -15474.555 | ... O11: =-'Cost Schedule'!O8 -> -29717.018
A12: Less: Delivery & related charges | B12: INR Cr | D12: =-'Cost Schedule'!D7 -> -2537 | E12: =-'Cost Schedule'!E7 -> -3915 | F12: =-'Cost Schedule'!F7 -> -5728 | G12: =-'Cost Schedule'!G7 -> -9065 | H12: =-'Cost Schedule'!H7 -> -21382.988 | I12: =-'Cost Schedule'!I7 -> -29149.417 | J12: =-'Cost Schedule'!J7 -> -38822.74 | K12: =-'Cost Schedule'!K7 -> -49716.125 | ... O12: =-'Cost Schedule'!O7 -> -101472.75
A13: Less: Advertisement & sales promotion | B13: INR Cr | D13: =-'Cost Schedule'!D11 -> -1227 | E13: =-'Cost Schedule'!E11 -> -1432 | F13: =-'Cost Schedule'!F11 -> -1972 | G13: =-'Cost Schedule'!G11 -> -3350 | H13: =-'Cost Schedule'!H11 -> -7617.6896 | I13: =-'Cost Schedule'!I11 -> -10025.914 | J13: =-'Cost Schedule'!J11 -> -12604.786 | K13: =-'Cost Schedule'!K11 -> -15803.801 | ... O13: =-'Cost Schedule'!O11 -> -30441.824
A14: Less: Other expenses (incl. cash lease rent, tech, G&A) | B14: INR Cr | D14: =-'Cost Schedule'!D12 -> -1665 | E14: =-'Cost Schedule'!E12 -> -2184 | F14: =-'Cost Schedule'!F12 -> -3783 | G14: =-'Cost Schedule'!G12 -> -7038 | H14: =-'Cost Schedule'!H12 -> -15595.185 | I14: =-'Cost Schedule'!I12 -> -19863.772 | J14: =-'Cost Schedule'!J12 -> -24512.531 | K14: =-'Cost Schedule'!K12 -> -28796.52 | ... O14: =-'Cost Schedule'!O12 -> -38935.248
A16: EBITDA (reported) | B16: INR Cr | D16: =SUM(D9,D11:D14) -> -1210 | E16: =SUM(E9,E11:E14) -> 42 | F16: =SUM(F9,F11:F14) -> 637 | G16: =SUM(G9,G11:G14) -> 1208 | H16: =SUM(H9,H11:H14) -> -5291.141 | I16: =SUM(I9,I11:I14) -> -3645.4179 | J16: =SUM(J9,J11:J14) -> -242.08899 | K16: =SUM(K9,K11:K14) -> 5618.783 | ... O16: =SUM(O9,O11:O14) -> 51847.403
A17: EBITDA margin (% of revenue) | B17: % | D17: =IFERROR(D16/D6,"") -> -0.1709281 | E17: =IFERROR(E16/E6,"") -> 0.0034670629 | F17: =IFERROR(F16/F6,"") -> 0.031467668 | G17: =IFERROR(G16/G6,"") -> 0.022220587 | H17: =IFERROR(H16/H6,"") -> -0.040530668 | I17: =IFERROR(I16/I6,"") -> -0.020088324 | J17: =IFERROR(J16/J6,"") -> -0.00098228675 | K17: =IFERROR(K16/K6,"") -> 0.017455585 | ... O17: =IFERROR(O16/O6,"") -> 0.073239733
